Workbook

Sheet AI Readiness Assessment
B1: AI READINESS ASSESSMENT QUESTIONNAIRE
B2: ASSESSMENT INSTRUCTIONS For each assessment statement, select the readiness score that best reflects your organisation's current level of capability. Score each question using the readiness scale below. Select the score that most accurately represents current practice rather than future aspirations. Where evidence is limited, choose the lower score. AI READINESS SCORING MODEL Score Maturity Level Description 1 Initial Limited awareness and ad hoc activities. AI capabilities are largely undefined and unmanaged. 2 Emerging Early planning and isolated initiatives. AI activities are beginning to develop but remain inconsistent. 3 Developing Defined capabilities with growing adoption. Formal processes exist and adoption is increasing. 4 Established Consistent practices and measurable outcomes. AI capabilities are integrated into business operations. 5 Optimised Enterprise-wide capability with continuous improvement. AI is embedded strategically and delivers measurable value at scale.
B3: Organisation Name | C3: Business Unit | D3: Assessment Date | E3: Assessment Lead | F3: Executive Sponsor
D6: CHOSEN LEVEL | E6: Initial | F6: Emerging | G6: Developing | H6: Established | I6: Optimised
C7: Evaluate each statement using the AI Maturity Scale (1–5) and select the level that best reflects your organisation's current capability. | E7: – 1 – | F7: – 2 – | G7: – 3 – | H7: – 4 – | I7: – 5 –
B8: STRATEGY & VISION | C8: A documented AI strategy exists and is approved by leadership. | D8: =SUM(E8:I8) -> 2 | F8: 2
C9: AI objectives are aligned with business priorities and strategic outcomes. | D9: =SUM(E9:I9) -> 0
C10: Executive sponsorship for AI initiatives is clearly established. | D10: =SUM(E10:I10) -> 0
C11: Funding and investment for AI initiatives are formally allocated. | D11: =SUM(E11:I11) -> 0
C12: AI success measures and KPIs are clearly defined. | D12: =SUM(E12:I12) -> 0
C13: A roadmap exists for enterprise AI adoption and scaling. | D13: =SUM(E13:I13) -> 0
C14: AI opportunities are regularly identified and prioritised. | D14: =SUM(E14:I14) -> 0
B15: LEADERSHIP & CULTURE | C15: Senior leaders actively promote AI adoption across the organisation. | D15: =SUM(E15:I15) -> 0
C16: AI is recognised as a strategic organisational capability. | D16: =SUM(E16:I16) -> 0
C17: The organisation encourages innovation and experimentation with AI. | D17: =SUM(E17:I17) -> 0
C18: Employees understand the purpose and benefits of AI initiatives. | D18: =SUM(E18:I18) -> 0
C19: Change management activities support AI adoption. | D19: =SUM(E19:I19) -> 0
C20: Leadership effectively communicates AI priorities and objectives. | D20: =SUM(E20:I20) -> 0
C21: Resistance to AI adoption is proactively managed. | D21: =SUM(E21:I21) -> 0
C22: Cross-functional collaboration supports AI-enabled transformation. | D22: =SUM(E22:I22) -> 0
B23: WORKFORCE & SKILLS | C23: Employees possess an appropriate level of AI literacy. | D23: =SUM(E23:I23) -> 1 | E23: 1
C24: AI training programmes are available to employees. | D24: =SUM(E24:I24) -> 0
C25: Specialist AI skills exist within the organisation. | D25: =SUM(E25:I25) -> 0
C26: Skills gaps relating to AI are regularly assessed. | D26: =SUM(E26:I26) -> 0
C27: AI learning pathways and development plans are established. | D27: =SUM(E27:I27) -> 0
C28: AI champions are identified across business functions. | D28: =SUM(E28:I28) -> 0
C29: Communities of practice support AI knowledge sharing. | D29: =SUM(E29:I29) -> 0
C30: Recruitment plans support future AI capability growth. | D30: =SUM(E30:I30) -> 0
B31: DATA READINESS | C31: Critical business data is readily accessible. | D31: =SUM(E31:I31) -> 0
C32: Data ownership and accountability are clearly defined. | D32: =SUM(E32:I32) -> 0
C33: Data quality is measured and monitored. | D33: =SUM(E33:I33) -> 0
C34: Data governance processes are established. | D34: =SUM(E34:I34) -> 0
C35: Data privacy controls are implemented and enforced. | D35: =SUM(E35:I35) -> 0
C36: Data lineage and traceability capabilities are available. | D36: =SUM(E36:I36) -> 0
C37: Structured and unstructured data support AI use cases. | D37: =SUM(E37:I37) -> 0
C38: Enterprise data standards are consistently applied. | D38: =SUM(E38:I38) -> 0
C39: Metadata management capabilities are established. | D39: =SUM(E39:I39) -> 0
C40: Data platforms adequately support AI initiatives. | D40: =SUM(E40:I40) -> 0
C41: Data required for AI initiatives is discoverable through a catalogue or inventory. | D41: =SUM(E41:I41) -> 0
C42: Sensitive data is appropriately classified for AI use. | D42: =SUM(E42:I42) -> 0
...

Sheet AI Maturity Matrix
B3: Domain | C3: Initial (1) | D3: Emerging (2) | E3: Developing (3) | F3: Established (4) | G3: Optimised (5)
B4: Strategy & Vision | C4: No formal AI strategy exists. | D4: AI opportunities are being explored and discussed. | E4: AI strategy has been drafted and partially aligned to business objectives. | F4: AI strategy is approved, funded and communicated. | G4: AI strategy is embedded into enterprise planning and continuously refined.
B5: Leadership & Culture | C5: Leadership awareness of AI is limited. | D5: Individual leaders support AI initiatives. | E5: Leadership engagement is growing across business functions. | F5: Active executive sponsorship and change leadership are in place. | G5: AI-driven culture is embedded throughout the organisation.
B6: Workforce & Skills | C6: Limited AI skills and awareness exist. | D6: Ad hoc AI training is available. | E6: Structured AI training and capability development programmes exist. | F6: AI capability development is actively managed and measured. | G6: Continuous AI learning and advanced expertise are embedded across the workforce.
B7: Data Readiness | C7: Data quality and accessibility issues significantly limit AI adoption. | D7: Data improvement initiatives are underway. | E7: Data governance and quality management practices are emerging. | F7: Data is managed consistently and supports AI initiatives. | G7: Data is treated as a strategic enterprise asset enabling AI at scale.
B8: Process & Operating Model | C8: AI processes and responsibilities are undefined. | D8: Initial governance and operating processes are being developed. | E8: Defined processes support AI initiatives in key areas. | F8: Standardised operating model supports AI delivery across the organisation. | G8: AI is fully integrated into business operations and decision-making processes.
B9: Technology & Architecture | C9: Technology landscape is not prepared for AI workloads. | D9: Early AI experimentation is supported by limited technology capabilities. | E9: AI platforms and supporting technologies have been introduced. | F9: Scalable and secure AI architecture is established. | G9: Enterprise-wide AI platform enables innovation, automation and continuous optimisation.
B10: Governance & Responsible AI | C10: No formal AI governance or oversight exists. | D10: Initial governance discussions and responsibilities have been identified. | E10: Governance processes and responsible AI controls are being established. | F10: Formal governance framework and oversight mechanisms are operational. | G10: Responsible AI is embedded throughout the AI lifecycle and continuously monitored.
B11: Security & Compliance | C11: AI-related security and compliance controls are largely absent. | D11: Initial security and compliance requirements have been identified. | E11: Security and compliance controls are being implemented. | F11: Security, privacy and compliance controls are consistently applied. | G11: AI risk, security and compliance are proactively managed and continuously improved.
B12: Use Case & Value Management | C12: AI opportunities are identified on an ad hoc basis. | D12: Initial use cases and pilots are being explored. | E12: AI use cases are prioritised and business cases are developed. | F12: Benefits and outcomes are measured and managed. | G12: AI portfolio management and value realisation are embedded across the enterprise.
B13: Vendor & Ecosystem Readiness | C13: No formal AI vendor or partner strategy exists. | D13: Initial vendor relationships are being explored. | E13: Strategic partners have been identified and engaged. | F13: Vendor governance and ecosystem management processes are established. | G13: A mature AI ecosystem accelerates innovation, capability and business value.

Sheet Scoring Engine
A1: AI Readiness Scoring Engine
A3: Domain | B3: Score
A4: Strategy & Vision | B4: =IFERROR(AVERAGEIF('AI Readiness Assessment'!D8:D14,">0",'AI Readiness Assessment'!D8:D14),"") -> 2
A5: Leadership & Culture | B5: =IFERROR(AVERAGEIF('AI Readiness Assessment'!D15:D22,">0",'AI Readiness Assessment'!D15:D22),"")
A6: Workforce & Skills | B6: =IFERROR(AVERAGEIF('AI Readiness Assessment'!D23:D30,">0",'AI Readiness Assessment'!D23:D30),"") -> 1
A7: Data Readiness | B7: =IFERROR(AVERAGEIF('AI Readiness Assessment'!D31:D42,">0",'AI Readiness Assessment'!D31:D42),"")
A8: Process & Operating Model | B8: =IFERROR(AVERAGEIF('AI Readiness Assessment'!D43:D50,">0",'AI Readiness Assessment'!D43:D50),"")
A9: Technology & Architecture | B9: =IFERROR(AVERAGEIF('AI Readiness Assessment'!D51:D61,">0",'AI Readiness Assessment'!D51:D61),"")
A10: Governance & Responsible AI | B10: =IFERROR(AVERAGEIF('AI Readiness Assessment'!D62:D72,">0",'AI Readiness Assessment'!D62:D72),"")
A11: Security & Compliance | B11: =IFERROR(AVERAGEIF('AI Readiness Assessment'!D73:D78,">0",'AI Readiness Assessment'!D73:D78),"")
A12: Use Case & Value Management | B12: =IFERROR(AVERAGEIF('AI Readiness Assessment'!D79:D84,">0",'AI Readiness Assessment'!D79:D84),"")
A13: Vendor & Ecosystem Readiness | B13: =IFERROR(AVERAGEIF('AI Readiness Assessment'!D85:D89,">0",'AI Readiness Assessment'!D85:D89),"")
A14: Overall AI Readiness Score | B14: =IFERROR(AVERAGEIF(B4:B13,">0",B4:B13),"") -> 1.5
A15: AI Maturity Level | B15: =IF(B14="","Not Started",IF(B14<2,"Initial",IF(B14<3,"Emerging",IF(B14<4,"Developing",IF(B14<4.5,"Established","Optimised"))))) -> Initial
A16: Risk Rating | B16: =IF(B14="","Not Started",IF(B14<2,"Critical Risk",IF(B14<3,"High Risk",IF(B14<4,"Moderate Risk",IF(B14<4.5,"Low Risk","Minimal Risk"))))) -> Critical Risk
A17: AI Readiness Index (/100) | B17: =IF(B14="","",ROUND((B14/5)*100,0)) -> 30
A18: Highest Scoring Dimension | B18: =IF(B14="","",INDEX(A4:A13,MATCH(MAX(B4:B13),B4:B13,0))) -> Strategy & Vision
A19: Lowest Scoring Dimension | B19: {=IF(B14="","",INDEX(A4:A13,MATCH(MIN(IF(B4:B13>0,B4:B13)),IF(B4:B13>0,B4:B13),0)))} -> Workforce & Skills
A20: Assessment Status | B20: =IF(COUNTIF('AI Readiness Assessment'!D8:D89,">0")=82,"Complete","In Progress") -> In Progress

Sheet Readiness Heatmap
A1: Domain | B1: Score | C1: Maturity Level | D1: Risk Rating
A2: Strategy & Vision | B2: ='Scoring Engine'!B4 -> 2 | C2: =IF(B2="","",IF(B2<2,"Initial",IF(B2<3,"Emerging",IF(B2<4,"Developing",IF(B2<4.5,"Established","Optimised"))))) -> Emerging | D2: =IF(B2="","",IF(B2<2,"Critical Risk",IF(B2<3,"High Risk",IF(B2<4,"Moderate Risk",IF(B2<4.5,"Low Risk","Minimal Risk"))))) -> High Risk
A3: Leadership & Culture | B3: ='Scoring Engine'!B5 | C3: =IF(B3="","",IF(B3<2,"Initial",IF(B3<3,"Emerging",IF(B3<4,"Developing",IF(B3<4.5,"Established","Optimised"))))) | D3: =IF(B3="","",IF(B3<2,"Critical Risk",IF(B3<3,"High Risk",IF(B3<4,"Moderate Risk",IF(B3<4.5,"Low Risk","Minimal Risk")))))
A4: Workforce & Skills | B4: ='Scoring Engine'!B6 -> 1 | C4: =IF(B4="","",IF(B4<2,"Initial",IF(B4<3,"Emerging",IF(B4<4,"Developing",IF(B4<4.5,"Established","Optimised"))))) -> Initial | D4: =IF(B4="","",IF(B4<2,"Critical Risk",IF(B4<3,"High Risk",IF(B4<4,"Moderate Risk",IF(B4<4.5,"Low Risk","Minimal Risk"))))) -> Critical Risk
A5: Data Readiness | B5: ='Scoring Engine'!B7 | C5: =IF(B5="","",IF(B5<2,"Initial",IF(B5<3,"Emerging",IF(B5<4,"Developing",IF(B5<4.5,"Established","Optimised"))))) | D5: =IF(B5="","",IF(B5<2,"Critical Risk",IF(B5<3,"High Risk",IF(B5<4,"Moderate Risk",IF(B5<4.5,"Low Risk","Minimal Risk")))))
A6: Process & Operating Model | B6: ='Scoring Engine'!B8 | C6: =IF(B6="","",IF(B6<2,"Initial",IF(B6<3,"Emerging",IF(B6<4,"Developing",IF(B6<4.5,"Established","Optimised"))))) | D6: =IF(B6="","",IF(B6<2,"Critical Risk",IF(B6<3,"High Risk",IF(B6<4,"Moderate Risk",IF(B6<4.5,"Low Risk","Minimal Risk")))))
A7: Technology & Architecture | B7: ='Scoring Engine'!B9 | C7: =IF(B7="","",IF(B7<2,"Initial",IF(B7<3,"Emerging",IF(B7<4,"Developing",IF(B7<4.5,"Established","Optimised"))))) | D7: =IF(B7="","",IF(B7<2,"Critical Risk",IF(B7<3,"High Risk",IF(B7<4,"Moderate Risk",IF(B7<4.5,"Low Risk","Minimal Risk")))))
A8: Governance & Responsible AI | B8: ='Scoring Engine'!B10 | C8: =IF(B8="","",IF(B8<2,"Initial",IF(B8<3,"Emerging",IF(B8<4,"Developing",IF(B8<4.5,"Established","Optimised"))))) | D8: =IF(B8="","",IF(B8<2,"Critical Risk",IF(B8<3,"High Risk",IF(B8<4,"Moderate Risk",IF(B8<4.5,"Low Risk","Minimal Risk")))))
A9: Security & Compliance | B9: ='Scoring Engine'!B11 | C9: =IF(B9="","",IF(B9<2,"Initial",IF(B9<3,"Emerging",IF(B9<4,"Developing",IF(B9<4.5,"Established","Optimised"))))) | D9: =IF(B9="","",IF(B9<2,"Critical Risk",IF(B9<3,"High Risk",IF(B9<4,"Moderate Risk",IF(B9<4.5,"Low Risk","Minimal Risk")))))
A10: Use Case & Value Management | B10: ='Scoring Engine'!B12 | C10: =IF(B10="","",IF(B10<2,"Initial",IF(B10<3,"Emerging",IF(B10<4,"Developing",IF(B10<4.5,"Established","Optimised"))))) | D10: =IF(B10="","",IF(B10<2,"Critical Risk",IF(B10<3,"High Risk",IF(B10<4,"Moderate Risk",IF(B10<4.5,"Low Risk","Minimal Risk")))))
A11: Vendor & Ecosystem Readiness | B11: ='Scoring Engine'!B13 | C11: =IF(B11="","",IF(B11<2,"Initial",IF(B11<3,"Emerging",IF(B11<4,"Developing",IF(B11<4.5,"Established","Optimised"))))) | D11: =IF(B11="","",IF(B11<2,"Critical Risk",IF(B11<3,"High Risk",IF(B11<4,"Moderate Risk",IF(B11<4.5,"Low Risk","Minimal Risk")))))

Sheet Drop-Down Keys - Do Not Delete
B1: DROP-DOWN KEYS
B2: CHOSEN LEVEL | C2: SCORE
B3: Initial | C3: 1
B4: Emerging | C4: 2
B5: Developing | C5: 3
B6: Established | C6: 4
B7: Optimised | C7: 5
C8: 0

Sheet Executive Dashboard
A1: Executive Dashboard | AI Readiness Assessment Workbook™
A3: Overall Readiness Score | B3: ='Scoring Engine'!B14 -> 1.5 | C3: AI Readiness Index | D3: ='Scoring Engine'!B17 -> 30 | E3: Current Maturity Level | F3: ='Scoring Engine'!B15 -> Initial
A4: Risk Indicator | B4: ='Scoring Engine'!B16 -> Critical Risk | C4: Top Performing Area | D4: =INDEX('Scoring Engine'!A4:A13,MATCH(MAX('Scoring Engine'!B4:B13),'Scoring Engine'!B4:B13,0)) -> Strategy & Vision | E4: Priority Improvement Area | F4: ='Scoring Engine'!B19 -> Workforce & Skills
A5: Priority Recommendation | B5: =IF('Scoring Engine'!B14<3,"Build foundational AI capabilities including strategy, governance and workforce readiness.",IF('Scoring Engine'!B14<4,"Formalise AI operating model, controls and technology enablement.","Focus on scaling AI adoption, value realisation and continuous optimisation.")) -> Build foundational AI capabilities including strategy, governance and workforce readiness.
A7: Dimension | B7: Score | C7: Status
A8: Strategy & Vision | B8: ='Readiness Heatmap'!B2 -> 2 | C8: ='Readiness Heatmap'!C2 -> Emerging
A9: Leadership & Culture | B9: ='Readiness Heatmap'!B3 | C9: ='Readiness Heatmap'!C3
A10: Workforce & Skills | B10: ='Readiness Heatmap'!B4 -> 1 | C10: ='Readiness Heatmap'!C4 -> Initial
A11: Data Readiness | B11: ='Readiness Heatmap'!B5 | C11: ='Readiness Heatmap'!C5
A12: Process & Operating Model | B12: ='Readiness Heatmap'!B6 | C12: ='Readiness Heatmap'!C6
A13: Technology & Architecture | B13: ='Readiness Heatmap'!B7 | C13: ='Readiness Heatmap'!C7
A14: Governance & Responsible AI | B14: ='Readiness Heatmap'!B8 | C14: ='Readiness Heatmap'!C8
A15: Security & Compliance | B15: ='Readiness Heatmap'!B9 | C15: ='Readiness Heatmap'!C9
A16: Use Case & Value Management | B16: ='Readiness Heatmap'!B10 | C16: ='Readiness Heatmap'!C10
A17: Vendor & Ecosystem Readiness | B17: ='Readiness Heatmap'!B11 | C17: ='Readiness Heatmap'!C11

Sheet Improvement Roadmap
A1: Improvement Roadmap
C4: Roadmap Item | D4: Formula
C5: Overall AI Readiness Score | D5: ='Scoring Engine'!B14 -> 1.5
C6: AI Maturity Level | D6: ='Scoring Engine'!B15 -> Initial
C7: Risk Rating | D7: ='Scoring Engine'!B16 -> Critical Risk
C8: Highest Scoring Domain | D8: ='Scoring Engine'!B18 -> Strategy & Vision
C9: Lowest Scoring Domain | D9: ='Scoring Engine'!B19 -> Workforce & Skills
C11: Executive Recommendation
C12: =IF('Scoring Engine'!B14="","Complete the AI Readiness Assessment to generate an executive recommendation.",IF('Scoring Engine'!B14<3,_xlfn._LONGTEXT("The organisation should prioritise foundational AI readiness activities over the next 0-3 months. Immediate focus should be placed on establishing executive sponsorship, defining an enterprise AI strategy, assigning governance ownership, improving data re","adiness and launching baseline AI literacy across the workforce."),IF('Scoring Engine'!B14<4,_xlfn._LONGTEXT("The organisation has a developing AI readiness profile. Over the next 3-6 months, focus should be placed on formalising the AI operating model, strengthening governance and risk controls, improving data quality, expanding AI literacy and progressing prior","ity AI use cases."),IF('Scoring Engine'!B14<4.5,_xlfn._LONGTEXT("The organisation has an established AI readiness position. Over the next 6-12 months, focus should shift toward scaling AI adoption, embedding performance management, enhancing executive reporting and strengthening value realisation across the AI portfoli","o."),"The organisation demonstrates an optimised AI readiness position. Focus should remain on continuous improvement, enterprise-wide value realisation, responsible AI assurance, advanced automation and sustained innovation.")))) -> The organisation should prioritise foundational AI readiness activities over the next 0-3 months. Immediate focus should be placed on establishing executive sponsorship, defining an enterprise AI strategy, assigning governance ownership, improving data readiness and launching baseline AI literacy across the workforce.
C17: Immediate Priorities (0–3 Months)
C19: Trigger: Domain Score < 3.0
C21: These are capability gaps that present a significant risk to AI adoption.
B23: Rank | C23: Domain | D23: Score | E23: Recommendation | F23: Priority
B24: 1 | C24: =IF(D24="","",INDEX('Scoring Engine'!$A$4:$A$13,MATCH(D24,'Scoring Engine'!$B$4:$B$13,0))) -> Workforce & Skills | D24: =IF(COUNT('Scoring Engine'!$B$4:$B$13)>=1,SMALL('Scoring Engine'!$B$4:$B$13,1),"") -> 1 | E24: =IF(C24="","",VLOOKUP(C24,'Domain Recommendation Library'!$B$7:$C$16,2,FALSE)) -> Establish AI literacy and capability development programmes. | F24: ="Immediate Priority (0–3 Months)" -> Immediate Priority (0–3 Months)
B25: 2 | C25: =IF(D25="","",INDEX('Scoring Engine'!$A$4:$A$13,MATCH(D25,'Scoring Engine'!$B$4:$B$13,0))) -> Strategy & Vision | D25: =IF(COUNT('Scoring Engine'!$B$4:$B$13)>=2,SMALL('Scoring Engine'!$B$4:$B$13,2),"") -> 2 | E25: =IF(C25="","",VLOOKUP(C25,'Domain Recommendation Library'!$B$7:$C$16,2,FALSE)) -> Develop and approve an enterprise AI strategy and roadmap. | F25: ="Immediate Priority (0–3 Months)" -> Immediate Priority (0–3 Months)
B26: 3 | C26: =IF(D26="","",INDEX('Scoring Engine'!$A$4:$A$13,MATCH(D26,'Scoring Engine'!$B$4:$B$13,0))) | D26: =IF(COUNT('Scoring Engine'!$B$4:$B$13)>=3,SMALL('Scoring Engine'!$B$4:$B$13,3),"") | E26: =IF(C26="","",VLOOKUP(C26,'Domain Recommendation Library'!$B$7:$C$16,2,FALSE)) | F26: ="Immediate Priority (0–3 Months)" -> Immediate Priority (0–3 Months)
C30: Medium-Term Priorities (3–6 Months)
C32: Trigger: Domain Score between 3.0 and 3.9
C34: These are developing capabilities requiring formalisation.
B36: Rank | C36: Domain | D36: Score | E36: Recommendation | F36: Priority
B37: 1 | C37: =IF(D37="","",INDEX('Scoring Engine'!$A$4:$A$13,MATCH(D37,'Scoring Engine'!$B$4:$B$13,0))) | D37: =IF(COUNT('Scoring Engine'!$B$4:$B$13)>=4,SMALL('Scoring Engine'!$B$4:$B$13,4),"") | E37: =IF(C37="","",VLOOKUP(C37,'Domain Recommendation Library'!$B$7:$C$16,2,FALSE)) | F37: ="Medium-Term Priority (3–6 Months)" -> Medium-Term Priority (3–6 Months)
B38: 2 | C38: =IF(D38="","",INDEX('Scoring Engine'!$A$4:$A$13,MATCH(D38,'Scoring Engine'!$B$4:$B$13,0))) | D38: =IF(COUNT('Scoring Engine'!$B$4:$B$13)>=5,SMALL('Scoring Engine'!$B$4:$B$13,5),"") | E38: =IF(C38="","",VLOOKUP(C38,'Domain Recommendation Library'!$B$7:$C$16,2,FALSE)) | F38: ="Medium-Term Priority (3–6 Months)" -> Medium-Term Priority (3–6 Months)
B39: 3 | C39: =IF(D39="","",INDEX('Scoring Engine'!$A$4:$A$13,MATCH(D39,'Scoring Engine'!$B$4:$B$13,0))) | D39: =IF(COUNT('Scoring Engine'!$B$4:$B$13)>=6,SMALL('Scoring Engine'!$B$4:$B$13,6),"") | E39: =IF(C39="","",VLOOKUP(C39,'Domain Recommendation Library'!$B$7:$C$16,2,FALSE)) | F39: ="Medium-Term Priority (3–6 Months)" -> Medium-Term Priority (3–6 Months)
C45: Strategic Optimisation (6–12 Months)
C47: Trigger: Domain Score ≥ 4
C49: These areas are mature and should focus on optimisation and scale.
B51: Rank | C51: Domain | D51: Score | E51: Recommendation | F51: Priority
B52: 1 | C52: =IF(D52="","",INDEX('Scoring Engine'!$A$4:$A$13,MATCH(D52,'Scoring Engine'!$B$4:$B$13,0))) -> Strategy & Vision | D52: =IF(COUNT('Scoring Engine'!$B$4:$B$13)>=1,LARGE('Scoring Engine'!$B$4:$B$13,1),"") -> 2 | E52: =IF(C52="","",VLOOKUP(C52,'Domain Recommendation Library'!$B$7:$C$16,2,FALSE)) -> Develop and approve an enterprise AI strategy and roadmap. | F52: ="Lower Priority (6–12 Months)" -> Lower Priority (6–12 Months)
B53: 2 | C53: =IF(D53="","",INDEX('Scoring Engine'!$A$4:$A$13,MATCH(D53,'Scoring Engine'!$B$4:$B$13,0))) -> Workforce & Skills | D53: =IF(COUNT('Scoring Engine'!$B$4:$B$13)>=2,LARGE('Scoring Engine'!$B$4:$B$13,2),"") -> 1 | E53: =IF(C53="","",VLOOKUP(C53,'Domain Recommendation Library'!$B$7:$C$16,2,FALSE)) -> Establish AI literacy and capability development programmes. | F53: ="Lower Priority (6–12 Months)" -> Lower Priority (6–12 Months)
B54: 3 | C54: =IF(D54="","",INDEX('Scoring Engine'!$A$4:$A$13,MATCH(D54,'Scoring Engine'!$B$4:$B$13,0))) | D54: =IF(COUNT('Scoring Engine'!$B$4:$B$13)>=3,LARGE('Scoring Engine'!$B$4:$B$13,3),"") | E54: =IF(C54="","",VLOOKUP(C54,'Domain Recommendation Library'!$B$7:$C$16,2,FALSE)) | F54: ="Lower Priority (6–12 Months)" -> Lower Priority (6–12 Months)

Sheet Executive Summary
A1: Consulting Executive Assessment Report
A3: Organisation Name
A4: Assessment Date | B4: ='AI Readiness Assessment'!D4 -> 0
A5: Assessment Lead | B5: ='AI Readiness Assessment'!E4 -> 0
A6: Executive Sponsor
B11: Overall AI Readiness Score | C11: ='Scoring Engine'!B14 -> 1.5
B12: AI Maturity Level | C12: ='Scoring Engine'!B15 -> Initial
B13: AI Readiness Index | C13: ='Scoring Engine'!B17 -> 30
B14: Risk Rating | C14: ='Scoring Engine'!B16 -> Critical Risk
A17: Top 3 Strengths | B17: Top 3 Improvement Areas
A18: =INDEX('Scoring Engine'!$A$4:$A$13,MATCH(LARGE('Scoring Engine'!$B$4:$B$13,1),'Scoring Engine'!$B$4:$B$13,0))&" ("&TEXT(LARGE('Scoring Engine'!$B$4:$B$13,1),"0.00")&")" -> Strategy & Vision (2.00) | B18: =INDEX('Scoring Engine'!$A$4:$A$13,MATCH(SMALL('Scoring Engine'!$B$4:$B$13,1),'Scoring Engine'!$B$4:$B$13,0))&" ("&TEXT(SMALL('Scoring Engine'!$B$4:$B$13,1),"0.00")&")" -> Workforce & Skills (1.00)
A19: =INDEX('Scoring Engine'!$A$4:$A$13,MATCH(LARGE('Scoring Engine'!$B$4:$B$13,2),'Scoring Engine'!$B$4:$B$13,0))&" ("&TEXT(LARGE('Scoring Engine'!$B$4:$B$13,2),"0.00")&")" -> Workforce & Skills (1.00) | B19: =INDEX('Scoring Engine'!$A$4:$A$13,MATCH(SMALL('Scoring Engine'!$B$4:$B$13,2),'Scoring Engine'!$B$4:$B$13,0))&" ("&TEXT(SMALL('Scoring Engine'!$B$4:$B$13,2),"0.00")&")" -> Strategy & Vision (2.00)
A20: =INDEX('Scoring Engine'!$A$4:$A$13,MATCH(LARGE('Scoring Engine'!$B$4:$B$13,3),'Scoring Engine'!$B$4:$B$13,0))&" ("&TEXT(LARGE('Scoring Engine'!$B$4:$B$13,3),"0.00")&")" -> #NUM! | B20: =INDEX('Scoring Engine'!$A$4:$A$13,MATCH(SMALL('Scoring Engine'!$B$4:$B$13,3),'Scoring Engine'!$B$4:$B$13,0))&" ("&TEXT(SMALL('Scoring Engine'!$B$4:$B$13,3),"0.00")&")" -> #NUM!
A22: Executive Recommendation
A23: =IF('Scoring Engine'!B14<3,"The organisation should prioritise core AI foundations before scaling enterprise use cases. Immediate focus should be on executive sponsorship, a documented AI strategy, governance ownership and policy development.",IF('Scoring Engine'!B14<4,"The organisation has a developing AI readiness profile. Management should formalise controls, expand AI literacy, strengthen risk governance and accelerate technology enablement.","The organisation is positioned to scale AI adoption. Focus should shift to enterprise operating model maturity, executive dashboards, value realisation and continuous improvement.")) -> The organisation should prioritise core AI foundations before scaling enterprise use cases. Immediate focus should be on executive sponsorship, a documented AI strategy, governance ownership and policy development.
A28: Roadmap Summary
A29: =IF('Scoring Engine'!B14<3,"0–3 Month Focus: Establish foundational AI capabilities including strategy, governance, executive sponsorship, AI literacy and data readiness.",IF('Scoring Engine'!B14<4,"3–6 Month Focus: Formalise the AI operating model, strengthen governance controls, improve data quality and scale priority AI use cases.","6–12 Month Focus: Optimise enterprise AI capability, enhance value realisation, mature executive reporting and drive continuous improvement.")) -> 0–3 Month Focus: Establish foundational AI capabilities including strategy, governance, executive sponsorship, AI literacy and data readiness.

Sheet Domain Recommendation Library
B3: Domain Recommendation Library
B6: Domain | C6: Recommendation
B7: Strategy & Vision | C7: Develop and approve an enterprise AI strategy and roadmap.
B8: Leadership & Culture | C8: Increase executive sponsorship and AI change leadership.
B9: Workforce & Skills | C9: Establish AI literacy and capability development programmes.
B10: Data Readiness | C10: Improve data governance, quality and accessibility.
B11: Process & Operating Model | C11: Define AI operating model and governance processes.
B12: Technology & Architecture | C12: Expand scalable AI infrastructure and platforms.
B13: Governance & Responsible AI | C13: Implement Responsible AI framework and controls.
B14: Security & Compliance | C14: Strengthen AI security, privacy and compliance oversight.
B15: Use Case & Value Management | C15: Formalise AI use case prioritisation and benefits tracking.
B16: Vendor & Ecosystem Readiness | C16: Establish strategic AI vendor and partner management.

Sheet Help Guide
A1: AI READINESS ASSESSMENT WORKBOOK™
A3: Instructions & Assessment Guide
A5: Purpose
A7: The AI Readiness Assessment is designed to help organisations evaluate their preparedness for the successful adoption, governance, and scaling of Artificial Intelligence (AI) capabilities across the enterprise.
A9: As organisations increasingly seek to leverage AI to improve operational efficiency, enhance decision-making, accelerate innovation, and create competitive advantage, it is essential to understand current readiness levels and identify capability gaps that may hinder successful implementation.
A11: This assessment provides a structured framework to evaluate key dimensions of AI readiness, enabling leaders to benchmark current capabilities, prioritise improvement initiatives, and develop a practical roadmap for enterprise AI adoption.
A13: The assessment includes a scoring methodology that measures maturity across multiple dimensions and generates actionable insights, recommendations, and improvement priorities.
A17: How to Use This Workbook
A19: Step 1 – Complete the Assessment Questionnaire
A21: Navigate to the Assessment Questionnaire worksheet and evaluate each assessment statement using the AI Maturity Scoring Model.
A23: Select the maturity score that best reflects your organisation's current state.
A25: Step 2 – Review Automated Scoring
... A251: Each assessment question should be scored using the following maturity scale:
A253: Score | B253: Maturity Level | C253: Description
A254: 1 | B254: Initial | C254: Limited awareness and ad hoc activities. AI capabilities are largely undefined and unmanaged.
A255: 2 | B255: Emerging | C255: Early planning and isolated initiatives. AI activities are beginning to develop but remain inconsistent.
A256: 3 | B256: Developing | C256: Defined capabilities with growing adoption. Formal processes exist and adoption is increasing.
A257: 4 | B257: Established | C257: Consistent practices and measurable outcomes. AI capabilities are integrated into business operations.
A258: 5 | B258: Optimised | C258: Enterprise-wide capability with continuous improvement. AI is embedded strategically and delivers measurable value at scale.
A261: Assessment Outputs
A263: Upon completion, the workbook will automatically generate:
A265: Overall AI Readiness Score
A267: AI Maturity Level
A269: Dimension-Level Scores
A271: Readiness Heatmap
A273: AI Readiness Radar Chart
A275: Executive Dashboard
A277: Risk Indicators
A279: Priority Improvement Areas
A281: Strategic Recommendations
A283: AI Adoption Roadmap
... A293: The insights generated from this assessment should be used to develop actionable improvement plans, strengthen governance and operating models, and accelerate the organisation's journey toward responsible, scalable, and value-driven AI adoption.
